Workbook

Sheet Sheet5
B3: Column Labels
B4: Carrier A | D4: Carrier B | F4: Carrier C | H4: Total Sum of Current_Cost | I4: Total Sum of Modeled_Cost
A5: Row Labels | B5: Sum of Current_Cost | C5: Sum of Modeled_Cost | D5: Sum of Current_Cost | E5: Sum of Modeled_Cost | F5: Sum of Current_Cost | G5: Sum of Modeled_Cost
A6: London | B6: 410 | C6: 507.03 | D6: 395 | E6: 489.8 | F6: 430 | G6: 520.9 | H6: 1235 | I6: 1517.73
A7: Mississauga | B7: 300 | C7: 101.11 | F7: 560 | G7: 191.6 | H7: 860 | I7: 292.71
A8: Montreal | B8: 1250 | C8: 1810.16 | D8: 580 | E8: 857.8 | F8: 650 | G8: 927.4 | H8: 2480 | I8: 3595.36
A9: Ottawa | B9: 610 | C9: 750.36 | D9: 1195 | E9: 1420.2 | F9: 570 | G9: 760.8 | H9: 2375 | I9: 2931.36
A10: Quebec City | B10: 1180 | C10: 2084.6 | D10: 2220 | E10: 3997 | H10: 3400 | I10: 6081.6
A11: Windsor | B11: 1080 | C11: 1325.41 | F11: 2170 | G11: 2515.6 | H11: 3250 | I11: 3841.01
A12: Grand Total | B12: 4830 | C12: 6578.67 | D12: 4390 | E12: 6764.8 | F12: 4380 | G12: 4916.3 | H12: 13600 | I12: 18259.77

Sheet Shipments
A1: Shipment_ID | B1: Origin | C1: Destination | D1: Mode | E1: Carrier | F1: Miles | G1: Weight_lbs | H1: Current_Cost | I1: Accessorial | J1: Service_Level | K1: Rate_Key | L1: Base_Cost | M1: Fuel_Cost | N1: Modeled_Cost | O1: Cost_per_Mile
A2: S001 | B2: Toronto | C2: Montreal | D2: LTL | E2: Carrier A | F2: 340 | G2: 1800 | H2: 620 | I2: 45 | J2: 0.96 | K2: =E2&"|"&D2 -> Carrier A|LTL | L2: =F2*_xlfn.XLOOKUP(K2,'Carrier Rates'!H:H,'Carrier Rates'!C:C) -> 731 | M2: =L2*_xlfn.XLOOKUP(K2,'Carrier Rates'!H:H,'Carrier Rates'!D:D) -> 131.58 | N2: =L2+M2+I2 -> 907.58 | O2: =N2/F2 -> 2.6693529
A3: S002 | B3: Toronto | C3: Ottawa | D3: LTL | E3: Carrier B | F3: 280 | G3: 2200 | H3: 590 | I3: 30 | J3: 0.93 | K3: =E3&"|"&D3 -> Carrier B|LTL | L3: =F3*_xlfn.XLOOKUP(K3,'Carrier Rates'!H:H,'Carrier Rates'!C:C) -> 560 | M3: =L3*_xlfn.XLOOKUP(K3,'Carrier Rates'!H:H,'Carrier Rates'!D:D) -> 117.6 | N3: =L3+M3+I3 -> 707.6 | O3: =N3/F3 -> 2.5271429
A4: S003 | B4: Toronto | C4: Windsor | D4: FTL | E4: Carrier C | F4: 370 | G4: 18000 | H4: 1050 | I4: 75 | J4: 0.97 | K4: =E4&"|"&D4 -> Carrier C|FTL | L4: =F4*_xlfn.XLOOKUP(K4,'Carrier Rates'!H:H,'Carrier Rates'!C:C) -> 1017.5 | M4: =L4*_xlfn.XLOOKUP(K4,'Carrier Rates'!H:H,'Carrier Rates'!D:D) -> 162.8 | N4: =L4+M4+I4 -> 1255.3 | O4: =N4/F4 -> 3.3927027
A5: S004 | B5: Toronto | C5: London | D5: LTL | E5: Carrier A | F5: 190 | G5: 1400 | H5: 410 | I5: 25 | J5: 0.97 | K5: =E5&"|"&D5 -> Carrier A|LTL | L5: =F5*_xlfn.XLOOKUP(K5,'Carrier Rates'!H:H,'Carrier Rates'!C:C) -> 408.5 | M5: =L5*_xlfn.XLOOKUP(K5,'Carrier Rates'!H:H,'Carrier Rates'!D:D) -> 73.53 | N5: =L5+M5+I5 -> 507.03 | O5: =N5/F5 -> 2.6685789
A6: S005 | B6: Toronto | C6: Quebec City | D6: LTL | E6: Carrier B | F6: 800 | G6: 2500 | H6: 1120 | I6: 60 | J6: 0.94 | K6: =E6&"|"&D6 -> Carrier B|LTL | L6: =F6*_xlfn.XLOOKUP(K6,'Carrier Rates'!H:H,'Carrier Rates'!C:C) -> 1600 | M6: =L6*_xlfn.XLOOKUP(K6,'Carrier Rates'!H:H,'Carrier Rates'!D:D) -> 336 | N6: =L6+M6+I6 -> 1996 | O6: =N6/F6 -> 2.495
A7: S006 | B7: Toronto | C7: Mississauga | D7: LTL | E7: Carrier C | F7: 30 | G7: 900 | H7: 285 | I7: 20 | J7: 0.98 | K7: =E7&"|"&D7 -> Carrier C|LTL | L7: =F7*_xlfn.XLOOKUP(K7,'Carrier Rates'!H:H,'Carrier Rates'!C:C) -> 67.5 | M7: =L7*_xlfn.XLOOKUP(K7,'Carrier Rates'!H:H,'Carrier Rates'!D:D) -> 10.8 | N7: =L7+M7+I7 -> 98.3 | O7: =N7/F7 -> 3.2766667
A8: S007 | B8: Toronto | C8: Montreal | D8: LTL | E8: Carrier B | F8: 340 | G8: 2100 | H8: 580 | I8: 35 | J8: 0.93 | K8: =E8&"|"&D8 -> Carrier B|LTL | L8: =F8*_xlfn.XLOOKUP(K8,'Carrier Rates'!H:H,'Carrier Rates'!C:C) -> 680 | M8: =L8*_xlfn.XLOOKUP(K8,'Carrier Rates'!H:H,'Carrier Rates'!D:D) -> 142.8 | N8: =L8+M8+I8 -> 857.8 | O8: =N8/F8 -> 2.5229412
A9: S008 | B9: Toronto | C9: Ottawa | D9: LTL | E9: Carrier A | F9: 280 | G9: 1900 | H9: 610 | I9: 40 | J9: 0.96 | K9: =E9&"|"&D9 -> Carrier A|LTL | L9: =F9*_xlfn.XLOOKUP(K9,'Carrier Rates'!H:H,'Carrier Rates'!C:C) -> 602 | M9: =L9*_xlfn.XLOOKUP(K9,'Carrier Rates'!H:H,'Carrier Rates'!D:D) -> 108.36 | N9: =L9+M9+I9 -> 750.36 | O9: =N9/F9 -> 2.6798571
A10: S009 | B10: Toronto | C10: Windsor | D10: FTL | E10: Carrier C | F10: 370 | G10: 20000 | H10: 1120 | I10: 80 | J10: 0.97 | K10: =E10&"|"&D10 -> Carrier C|FTL | L10: =F10*_xlfn.XLOOKUP(K10,'Carrier Rates'!H:H,'Carrier Rates'!C:C) -> 1017.5 | M10: =L10*_xlfn.XLOOKUP(K10,'Carrier Rates'!H:H,'Carrier Rates'!D:D) -> 162.8 | N10: =L10+M10+I10 -> 1260.3 | O10: =N10/F10 -> 3.4062162
A11: S010 | B11: Toronto | C11: London | D11: LTL | E11: Carrier B | F11: 190 | G11: 1600 | H11: 395 | I11: 30 | J11: 0.94 | K11: =E11&"|"&D11 -> Carrier B|LTL | L11: =F11*_xlfn.XLOOKUP(K11,'Carrier Rates'!H:H,'Carrier Rates'!C:C) -> 380 | M11: =L11*_xlfn.XLOOKUP(K11,'Carrier Rates'!H:H,'Carrier Rates'!D:D) -> 79.8 | N11: =L11+M11+I11 -> 489.8 | O11: =N11/F11 -> 2.5778947
A12: S011 | B12: Toronto | C12: Quebec City | D12: LTL | E12: Carrier A | F12: 800 | G12: 2800 | H12: 1180 | I12: 55 | J12: 0.96 | K12: =E12&"|"&D12 -> Carrier A|LTL | L12: =F12*_xlfn.XLOOKUP(K12,'Carrier Rates'!H:H,'Carrier Rates'!C:C) -> 1720 | M12: =L12*_xlfn.XLOOKUP(K12,'Carrier Rates'!H:H,'Carrier Rates'!D:D) -> 309.6 | N12: =L12+M12+I12 -> 2084.6 | O12: =N12/F12 -> 2.60575
A13: S012 | B13: Toronto | C13: Mississauga | D13: LTL | E13: Carrier A | F13: 30 | G13: 1100 | H13: 300 | I13: 25 | J13: 0.97 | K13: =E13&"|"&D13 -> Carrier A|LTL | L13: =F13*_xlfn.XLOOKUP(K13,'Carrier Rates'!H:H,'Carrier Rates'!C:C) -> 64.5 | M13: =L13*_xlfn.XLOOKUP(K13,'Carrier Rates'!H:H,'Carrier Rates'!D:D) -> 11.61 | N13: =L13+M13+I13 -> 101.11 | O13: =N13/F13 -> 3.3703333
... A21: S020 | B21: Toronto | C21: Ottawa | D21: LTL | E21: Carrier C | F21: 280 | G21: 2100 | H21: 570 | I21: 30 | J21: 0.98 | K21: =E21&"|"&D21 -> Carrier C|LTL | L21: =F21*_xlfn.XLOOKUP(K21,'Carrier Rates'!H:H,'Carrier Rates'!C:C) -> 630 | M21: =L21*_xlfn.XLOOKUP(K21,'Carrier Rates'!H:H,'Carrier Rates'!D:D) -> 100.8 | N21: =L21+M21+I21 -> 760.8 | O21: =N21/F21 -> 2.7171429

Sheet Carrier Rates
A1: Carrier | B1: Mode | C1: Rate_per_Mile | D1: Fuel_Surcharge | E1: Minimum_Charge | F1: Accessorial | G1: Service_Level | H1: Rate_Key
A2: Carrier A | B2: LTL | C2: 2.15 | D2: 0.18 | E2: 450 | F2: 35 | G2: 0.96 | H2: =A2&"|"&B2 -> Carrier A|LTL
A3: Carrier B | B3: LTL | C3: 2 | D3: 0.21 | E3: 475 | F3: 30 | G3: 0.93 | H3: =A3&"|"&B3 -> Carrier B|LTL
A4: Carrier C | B4: LTL | C4: 2.25 | D4: 0.16 | E4: 425 | F4: 40 | G4: 0.98 | H4: =A4&"|"&B4 -> Carrier C|LTL
A5: Carrier A | B5: FTL | C5: 2.9 | D5: 0.17 | E5: 900 | F5: 70 | G5: 0.96 | H5: =A5&"|"&B5 -> Carrier A|FTL
A6: Carrier C | B6: FTL | C6: 2.75 | D6: 0.16 | E6: 850 | F6: 80 | G6: 0.98 | H6: =A6&"|"&B6 -> Carrier C|FTL

Sheet Analysis
A1: Transportation Network Optimization Summary
A2: Current Transportation Spend | B2: =SUM(Shipments!H2:H21) -> 13600
A3: Modeled Transportation Spend | B3: =SUM(H10:H15) -> 19753.16
A4: Modeled Cost Variance | B4: =B2-B3 -> -6153.16
A5: Average Service Level | B5: =AVERAGE(Shipments!J2:J21) -> 0.9595
A6: Total Shipments | B6: =COUNTA(Shipments!A2:A21) -> 20
A8: Lane-Level Carrier Cost Analysis
A9: Destination | B9: Shipments | C9: Current Cost | D9: Carrier A Cost | E9: Carrier B Cost | F9: Carrier C Cost | G9: Recommended Carrier | H9: Optimized Cost | I9: Savings | J9: Savings %
A10: Montreal | B10: =COUNTIF(Shipments!$C:$C,A10) -> 4 | C10: =SUMIF(Shipments!$C:$C,A10,Shipments!$H:$H) -> 2480 | D10: =B10*(MAX(AVERAGEIF(Shipments!$C:$C,$A10,Shipments!$F:$F)*2.15,450)*(1+18%)+35) -> 3590.32 | E10: =B10*(MAX(AVERAGEIF(Shipments!$C:$C,$A10,Shipments!$F:$F)*2,475)*(1+21%)+30) -> 3411.2 | F10: =B10*(MAX(AVERAGEIF(Shipments!$C:$C,$A10,Shipments!$F:$F)*2.25,425)*(1+16%)+40) -> 3709.6 | G10: =IF(D10<=F10,"Carrier A","Carrier C") -> Carrier A | H10: =MIN(D10,F10) -> 3590.32 | I10: =C10-H10 -> -1110.32 | J10: =I10/C10 -> -0.44770968
A11: Ottawa | B11: =COUNTIF(Shipments!$C:$C,A11) -> 4 | C11: =SUMIF(Shipments!$C:$C,A11,Shipments!$H:$H) -> 2375 | D11: =B11*(MAX(AVERAGEIF(Shipments!$C:$C,$A11,Shipments!$F:$F)*2.15,450)*(1+18%)+35) -> 2981.44 | E11: =B11*(MAX(AVERAGEIF(Shipments!$C:$C,$A11,Shipments!$F:$F)*2,475)*(1+21%)+30) -> 2830.4 | F11: =B11*(MAX(AVERAGEIF(Shipments!$C:$C,$A11,Shipments!$F:$F)*2.25,425)*(1+16%)+40) -> 3083.2 | G11: =IF(D11<=F11,"Carrier A","Carrier C") -> Carrier A | H11: =MIN(D11,F11) -> 2981.44 | I11: =C11-H11 -> -606.44 | J11: =I11/C11 -> -0.25534316
A12: Windsor | B12: =COUNTIF(Shipments!$C:$C,A12) -> 3 | C12: =SUMIF(Shipments!$C:$C,A12,Shipments!$H:$H) -> 3250 | D12: =B12*(MAX(AVERAGEIF(Shipments!$C:$C,$A12,Shipments!$F:$F)*2.9,900)*(1+17%)+70) -> 3976.23 | E12: N/A | F12: =B12*(MAX(AVERAGEIF(Shipments!$C:$C,$A12,Shipments!$F:$F)*2.75,850)*(1+16%)+80) -> 3780.9 | G12: =IF(D12<=F12,"Carrier A","Carrier C") -> Carrier C | H12: =MIN(D12,F12) -> 3780.9 | I12: =C12-H12 -> -530.9 | J12: =I12/C12 -> -0.16335385
A13: London | B13: =COUNTIF(Shipments!$C:$C,A13) -> 3 | C13: =SUMIF(Shipments!$C:$C,A13,Shipments!$H:$H) -> 1235 | D13: =B13*(MAX(AVERAGEIF(Shipments!$C:$C,$A13,Shipments!$F:$F)*2.15,450)*(1+18%)+35) -> 1698 | E13: =B13*(MAX(AVERAGEIF(Shipments!$C:$C,$A13,Shipments!$F:$F)*2,475)*(1+21%)+30) -> 1814.25 | F13: =B13*(MAX(AVERAGEIF(Shipments!$C:$C,$A13,Shipments!$F:$F)*2.25,425)*(1+16%)+40) -> 1607.7 | G13: =IF(D13<=F13,"Carrier A","Carrier C") -> Carrier C | H13: =MIN(D13,F13) -> 1607.7 | I13: =C13-H13 -> -372.7 | J13: =I13/C13 -> -0.30178138
A14: Quebec City | B14: =COUNTIF(Shipments!$C:$C,A14) -> 3 | C14: =SUMIF(Shipments!$C:$C,A14,Shipments!$H:$H) -> 3400 | D14: =B14*(MAX(AVERAGEIF(Shipments!$C:$C,$A14,Shipments!$F:$F)*2.15,450)*(1+18%)+35) -> 6193.8 | E14: =B14*(MAX(AVERAGEIF(Shipments!$C:$C,$A14,Shipments!$F:$F)*2,475)*(1+21%)+30) -> 5898 | F14: =B14*(MAX(AVERAGEIF(Shipments!$C:$C,$A14,Shipments!$F:$F)*2.25,425)*(1+16%)+40) -> 6384 | G14: =IF(D14<=F14,"Carrier A","Carrier C") -> Carrier A | H14: =MIN(D14,F14) -> 6193.8 | I14: =C14-H14 -> -2793.8 | J14: =I14/C14 -> -0.82170588
A15: Mississauga | B15: =COUNTIF(Shipments!$C:$C,A15) -> 3 | C15: =SUMIF(Shipments!$C:$C,A15,Shipments!$H:$H) -> 860 | D15: =B15*(MAX(AVERAGEIF(Shipments!$C:$C,$A15,Shipments!$F:$F)*2.15,450)*(1+18%)+35) -> 1698 | E15: =B15*(MAX(AVERAGEIF(Shipments!$C:$C,$A15,Shipments!$F:$F)*2,475)*(1+21%)+30) -> 1814.25 | F15: =B15*(MAX(AVERAGEIF(Shipments!$C:$C,$A15,Shipments!$F:$F)*2.25,425)*(1+16%)+40) -> 1599 | G15: =IF(D15<=F15,"Carrier A","Carrier C") -> Carrier C | H15: =MIN(D15,F15) -> 1599 | I15: =C15-H15 -> -739 | J15: =I15/C15 -> -0.85930233
A17: Negotiated Rate Scenario — Procurement & Network Optimization
A18: Destination | B18: Current Cost | C18: Negotiated Cost | D18: Variance | E18: Variance % | F18: Recommendation
A19: Montreal | B19: =C10 -> 2480 | C19: =H10*90% -> 3231.288 | D19: =B19-C19 -> -751.288 | E19: =D19/B19 -> -0.30293871 | F19: =IF(D19>0,"Implement negotiated rate","Retain current network") -> Retain current network
A20: Ottawa | B20: =C11 -> 2375 | C20: =H11*90% -> 2683.296 | D20: =B20-C20 -> -308.296 | E20: =D20/B20 -> -0.12980884 | F20: =IF(D20>0,"Implement negotiated rate","Retain current network") -> Retain current network
A21: Windsor | B21: =C12 -> 3250 | C21: =H12*90% -> 3402.81 | D21: =B21-C21 -> -152.81 | E21: =D21/B21 -> -0.047018462 | F21: =IF(D21>0,"Implement negotiated rate","Retain current network") -> Retain current network
A22: London | B22: =C13 -> 1235 | C22: =H13*90% -> 1446.93 | D22: =B22-C22 -> -211.93 | E22: =D22/B22 -> -0.17160324 | F22: =IF(D22>0,"Implement negotiated rate","Retain current network") -> Retain current network
A23: Quebec City | B23: =C14 -> 3400 | C23: =H14*90% -> 5574.42 | D23: =B23-C23 -> -2174.42 | E23: =D23/B23 -> -0.63953529 | F23: =IF(D23>0,"Implement negotiated rate","Retain current network") -> Retain current network
A24: Mississauga | B24: =C15 -> 860 | C24: =H15*90% -> 1439.1 | D24: =B24-C24 -> -579.1 | E24: =D24/B24 -> -0.67337209 | F24: =IF(D24>0,"Implement negotiated rate","Retain current network") -> Retain current network
A25: Scenario Assumption: Simulated carrier rate reductions based on procurement negotiation and volume commitments; actual rates require carrier validation.
A26: Carrier Rate Sensitivity & Scenario Analysis
A27: Destination | B27: Current Cost | C27: 5% Rate Reduction | D27: 10% Rate Reduction | E27: 15% Rate Reduction
A28: Montreal | B28: =C10 -> 2480 | C28: =H10*95% -> 3410.804 | D28: =H10*90% -> 3231.288 | E28: =H10*85% -> 3051.772
A29: Ottawa | B29: =C11 -> 2375 | C29: =H11*95% -> 2832.368 | D29: =H11*90% -> 2683.296 | E29: =H11*85% -> 2534.224
A30: Windsor | B30: =C12 -> 3250 | C30: =H12*95% -> 3591.855 | D30: =H12*90% -> 3402.81 | E30: =H12*85% -> 3213.765
A31: London | B31: =C13 -> 1235 | C31: =H13*95% -> 1527.315 | D31: =H13*90% -> 1446.93 | E31: =H13*85% -> 1366.545
A32: Quebec City | B32: =C14 -> 3400 | C32: =H14*95% -> 5884.11 | D32: =H14*90% -> 5574.42 | E32: =H14*85% -> 5264.73
A33: Mississauga | B33: =C15 -> 860 | C33: =H15*95% -> 1519.05 | D33: =H15*90% -> 1439.1 | E33: =H15*85% -> 1359.15
A35: Carrier Switch Break-Even Analysis
A36: Destination | B36: Current Cost | C36: Optimized Cost | D36: Break-even Discount
A37: Montreal | B37: =C10 -> 2480 | C37: =H10 -> 3590.32 | D37: =1-(B37/C37) -> 0.30925377
A38: Ottawa | B38: =C11 -> 2375 | C38: =H11 -> 2981.44 | D38: =1-(B38/C38) -> 0.20340507
A39: Windsor | B39: =C12 -> 3250 | C39: =H12 -> 3780.9 | D39: =1-(B39/C39) -> 0.1404163
A40: London | B40: =C13 -> 1235 | C40: =H13 -> 1607.7 | D40: =1-(B40/C40) -> 0.23182186
A41: Quebec City | B41: =C14 -> 3400 | C41: =H14 -> 6193.8 | D41: =1-(B41/C41) -> 0.45106397
A42: Mississauga | B42: =C15 -> 860 | C42: =H15 -> 1599 | D42: =1-(B42/C42) -> 0.46216385
A44: Service-Level Constraint Analysis
...

Sheet Dashboard
B2: TRANSPORTATION NETWORK OPTIMIZATION
B3: Executive Dashboard | Carrier Strategy & Network Analysis
B5: CURRENT TRANSPORTATION SPEND | F5: MODELED TRANSPORTATION SPEND | J5: MODELED COST VARIANCE
B7: =Analysis!B2 -> 13600 | F7: =Analysis!B3 -> 19753.16 | J7: =Analysis!B4 -> -6153.16
B10: AVERAGE SERVICE LEVEL | F10: ELIGIBLE CARRIERS
B12: =Analysis!B5 -> 0.9595 | F12: =COUNTIF(Analysis!C46:C48,"Yes") -> 2
B16: Destination | C16: Current Cost | D16: Modeled Cost | F16: Destination | G16: Break-even Discount
B17: =Analysis!A10 -> Montreal | C17: =Analysis!C10 -> 2480 | D17: =Analysis!H10 -> 3590.32 | F17: =Analysis!A10 -> Montreal | G17: =Analysis!D37 -> 0.30925377
B18: =Analysis!A11 -> Ottawa | C18: =Analysis!C11 -> 2375 | D18: =Analysis!H11 -> 2981.44 | F18: =Analysis!A11 -> Ottawa | G18: =Analysis!D38 -> 0.20340507
B19: =Analysis!A12 -> Windsor | C19: =Analysis!C12 -> 3250 | D19: =Analysis!H12 -> 3780.9 | F19: =Analysis!A12 -> Windsor | G19: =Analysis!D39 -> 0.1404163
B20: =Analysis!A13 -> London | C20: =Analysis!C13 -> 1235 | D20: =Analysis!H13 -> 1607.7 | F20: =Analysis!A13 -> London | G20: =Analysis!D40 -> 0.23182186
B21: =Analysis!A14 -> Quebec City | C21: =Analysis!C14 -> 3400 | D21: =Analysis!H14 -> 6193.8 | F21: =Analysis!A14 -> Quebec City | G21: =Analysis!D41 -> 0.45106397
B22: =Analysis!A15 -> Mississauga | C22: =Analysis!C15 -> 860 | D22: =Analysis!H15 -> 1599 | F22: =Analysis!A15 -> Mississauga | G22: =Analysis!D42 -> 0.46216385
J32: Carrier | K32: Service Level | L32: Required Level
J33: Carrier A | K33: =Analysis!B46 -> 0.96 | L33: =95% -> 0.95
J34: Carrier B | K34: =Analysis!B47 -> 0.93 | L34: =95% -> 0.95
J35: Carrier C | K35: =Analysis!B48 -> 0.98 | L35: =95% -> 0.95
B42: KEY NETWORK RECOMMENDATION Maintain the current carrier network where modeled alternatives do not provide a cost advantage. Exclude Carrier B where its 93% service level falls below the 95% requirement. Prioritize procurement negotiations on lanes with the lowest break-even discount thresholds, particularly Windsor and Ottawa.
B49: KEY INSIGHT Modeled alternative carrier costs are higher than current transportation spend on all six analyzed lanes. A carrier switch therefore does not currently create a modeled cost advantage. The optimization should focus on commercial negotiation and selective lane-level opportunities rather than broad network conversion. | J49: METHODOLOGY NOTE Simulated portfolio scenario using modeled carrier rates, fuel surcharges, accessorial charges, service-level constraints, and procurement assumptions. Actual carrier rates, contracts, capacity, accessorials, and service commitments require validation before implementation.
B56: SCENARIO INSIGHT The modeled negotiation scenario assumes a simulated 10% reduction in alternative carrier rates based on procurement negotiation and volume commitments. Even after the reduction, modeled alternatives remain above the current network cost on the analyzed lanes, reinforcing the need for lane-specific negotiation rather than broad carrier conversion.

Sheet Requirements & Solution Design
A1: TRANSPORTATION NETWORK SOLUTION DESIGN
A3: Client Requirements | Data Inputs | Operational Constraints | Solution Architecture
A5: 1. CLIENT REQUIREMENTS & BUSINESS OBJECTIVES
A6: Requirement ID | B6: Requirement | C6: Business Objective | D6: Priority | E6: Success Metric | F6: Solution Response
A7: REQ-01 | B7: Reduce transportation cost without degrading service | C7: Identify economically viable lane and carrier opportunities | D7: High | E7: Cost parity or improvement | F7: Lane-level cost model and break-even analysis
A8: REQ-02 | B8: Maintain minimum service performance | C8: Protect customer service and delivery reliability | D8: High | E8: Service level ≥95% | F8: Carrier eligibility constraint in optimization
A9: REQ-03 | B9: Evaluate carrier alternatives and negotiation opportunities | C9: Support procurement strategy | D9: High | E9: Required discount by lane | F9: Rate sensitivity and negotiated-rate scenarios
A10: REQ-04 | B10: Validate operational feasibility before implementation | C10: Avoid non-executable network recommendations | D10: High | E10: Capacity and constraint sign-off | F10: Feasibility checklist and implementation gate
A11: REQ-05 | B11: Create reusable data and reporting process | C11: Enable repeatable decision support | D11: Medium | E11: Refreshable data model | F11: TMS/WMS/SQL data architecture and BI layer
A12: REQ-06 | B12: Provide executive-ready recommendations | C12: Support stakeholder decisions | D12: Medium | E12: Decision-ready dashboard | F12: Executive dashboard and implementation handoff
A15: 2. SOLUTION ARCHITECTURE & DATA FLOW
A16: Layer | B16: Primary System / Tool | C16: Key Data | D16: Transformation / Validation | E16: Output | F16: Owner
A17: Source | B17: TMS | C17: Shipments, lanes, modes, carrier, cost | D17: Required fields; duplicate shipment check | E17: Validated transportation fact table | F17: Transportation / IT
A18: Source | B18: WMS | C18: Orders, ship dates, facility data | D18: Order-to-shipment reconciliation | E18: Operational context | F18: Operations / IT
A19: Source | B19: Carrier / Procurement | C19: Rates, fuel, accessorials, service commitments | D19: Rate-effective-date and accessorial checks | E19: Validated rate table | F19: Procurement
A20: Data Layer | B20: SQL | C20: Joined shipment, rate and service data | D20: Business rules and scenario calculations | E20: Analysis-ready dataset | F20: Analytics
A21: Model | B21: Excel | C21: Cost, sensitivity, break-even, constraints | D21: Formula and assumption controls | E21: Scenario model | F21: Solutions Architect
A22: Reporting | B22: Power BI / Tableau | C22: KPIs and lane recommendations | D22: Refresh and reconciliation checks | E22: Executive dashboard | F22: Analytics / Leadership
A25: 3. OPERATIONAL FEASIBILITY & VALIDATION GATES
A26: Validation Area | B26: Question / Control | C26: Owner | D26: Status | E26: Evidence Required | F26: Implementation Gate
A27: Carrier Capacity | B27: Can the selected carrier support forecasted volume? | C27: Procurement | D27: Pending | E27: Written capacity confirmation | F27: Go / No-Go
A28: Service | B28: Can ≥95% service performance be contractually supported? | C28: Operations | D28: Pending | E28: Service KPI history / commitment | F28: Go / No-Go
A29: Accessorials | B29: Are modeled accessorial assumptions contractually accurate? | C29: Procurement | D29: Pending | E29: Rate sheet validation | F29: Go / No-Go
A30: Systems | B30: Can TMS/WMS master data support the proposed routing? | C30: IT | D30: Pending | E30: Configuration review | F30: Go / No-Go
A31: Commercial | B31: Are contract, liability and termination conditions acceptable? | C31: Legal / Procurement | D31: Pending | E31: Contract review | F31: Go / No-Go
A34: 4. DATA QUALITY & VALIDATION RULES
A35: Rule ID | B35: Data Element | C35: Validation Rule | D35: Exception Handling | E35: Owner | F35: Status
A36: DQ-01 | B36: Shipment ID | C36: Must be unique and nonblank | D36: Reject duplicate or missing records | E36: Data Owner | F36: Defined
A37: DQ-02 | B37: Lane | C37: Origin and destination must map to approved geography | D37: Route to data steward | E37: Transportation | F37: Defined
A38: DQ-03 | B38: Carrier Rate | C38: Rate must have effective date and lane coverage | D38: Exclude invalid rate from scenario | E38: Procurement | F38: Defined
A39: DQ-04 | B39: Service Level | C39: Value must be between 0% and 100% | D39: Flag and investigate | E39: Operations | F39: Defined
A40: DQ-05 | B40: Cost Components | C40: Base, fuel and accessorial logic must reconcile | D40: Hold scenario output | E40: Analytics | F40: Defined

Sheet Data Dictionary
A1: DATA DICTIONARY & COST MODEL DOCUMENTATION
A3: Definitions, Business Rules & Data Validation Ownership
A5: DATA DEFINITIONS & BUSINESS RULES
A6: Field | B6: Definition | C6: Source System | D6: Data Type | E6: Validation Rule | F6: Used In | G6: Owner
A7: Shipment ID | B7: Unique shipment identifier | C7: TMS | D7: Text | E7: Must be unique and nonblank | F7: SQL / BI / Excel | G7: Transportation
A8: Destination | B8: Destination market or city | C8: TMS | D8: Text | E8: Must map to approved geography | F8: Lane analysis | G8: Transportation
A9: Current Cost | B9: Current network transportation spend | C9: TMS / Finance | D9: Currency | E9: Reconcile to transportation spend extract | F9: KPI / Cost Model | G9: Finance
A10: Carrier Rate | B10: Modeled carrier lane rate | C10: Carrier / Procurement | D10: Currency | E10: Validate effective date and lane coverage | F10: Scenario Model | G10: Procurement
A11: Fuel Surcharge | B11: Modeled fuel adjustment | C11: Carrier Contract | D11: Currency / Percentage | E11: Validate against contract logic | F11: Cost Model | G11: Procurement
A12: Accessorial | B12: Additional transportation charge | C12: Carrier / TMS | D12: Currency | E12: Validate reason codes and charges | F12: Cost Model | G12: Operations
A13: Service Level | B13: On-time or service performance | C13: TMS / Carrier KPI | D13: Percentage | E13: Must be between 0% and 100% | F13: Eligibility Constraint | G13: Operations
A14: Eligible | B14: Carrier meets minimum 95% service threshold | C14: Calculated | D14: Boolean | E14: Based on service-level rule | F14: Optimization | G14: Solutions Architect
A15: Break-even Discount | B15: Discount required for modeled option to reach current cost | C15: Calculated | D15: Percentage | E15: Validate against cost formula | F15: Negotiation Strategy | G15: Solutions Architect

Sheet Implementation & Handoff
A1: IMPLEMENTATION & HANDOFF PLAN
A3: From Approved Solution Design to Controlled Network Deployment
A5: IMPLEMENTATION WORKPLAN
A6: Phase | B6: Activity | C6: Owner | D6: Deliverable | E6: Decision Gate | F6: Dependency | G6: Status | H6: Timing
A7: 1. Validate | B7: Validate shipment, rate, fuel and accessorial assumptions | C7: Solutions Architect / Procurement | D7: Signed-off baseline | E7: Data approved | F7: Source extracts | G7: Planned | H7: Week 1
A8: 2. Design | B8: Confirm target lanes, carriers and service constraints | C8: Solutions Architect / Operations | D8: Approved solution design | E8: Design approved | F8: Validated baseline | G8: Planned | H8: Week 1–2
A9: 3. Configure | B9: Update TMS routing guide and carrier master data | C9: IT / Transportation | D9: Configured test environment | E9: Configuration complete | F9: Approved design | G9: Planned | H9: Week 2–3
A10: 4. Test | B10: Run parallel cost and operational scenario testing | C10: Operations / Analytics | D10: Test results and exceptions log | E10: Test pass | F10: Configured environment | G10: Planned | H10: Week 3
A11: 5. Implement | B11: Execute phased lane and carrier changes | C11: Transportation / Procurement | D11: Go-live | E11: Go-live approval | F11: Test pass | G11: Planned | H11: Week 4
A12: 6. Monitor | B12: Track cost, service and exceptions against baseline | C12: Operations / Analytics | D12: 30-day performance review | E12: Stabilization accepted | F12: Go-live | G12: Planned | H12: Weeks 5–8
A15: HANDOFF & GOVERNANCE
A16: Artifact | B16: Purpose | C16: Primary Owner | D16: Audience | E16: Frequency | F16: Acceptance Criteria | G16: Repository | H16: Status
A17: Rate & Assumption Register | B17: Controls scenario assumptions | C17: Solutions Architect | D17: Procurement / Operations | E17: Per change | F17: Owner sign-off | G17: Project workspace | H17: Required
A18: Data Dictionary | B18: Defines fields and business rules | C18: Analytics | D18: IT / BI | E18: Quarterly | F18: Data owner approval | G18: Data repository | H18: Required
A19: Executive Dashboard | B19: Tracks cost and service outcomes | C19: Analytics | D19: Leadership | E19: Weekly / Monthly | F19: KPI reconciliation | G19: BI workspace | H19: Required
A20: Exception Log | B20: Captures operational issues | C20: Operations | D20: Project team | E20: Daily during rollout | F20: Closed or accepted risk | G20: TMS / Project log | H20: Required
A21: Implementation Runbook | B21: Documents deployment steps and rollback | C21: Solutions Architect / IT | D21: Implementation team | E21: Per release | F21: Go-live readiness approval | G21: Project workspace | H21: Required

Sheet README
A1: PORTFOLIO CASE STUDY — TRANSPORTATION NETWORK OPTIMIZATION
A3: Solutions Architect | Transportation Network Strategy / Supply Chain
A5: PROJECT OVERVIEW
A6: This simulated portfolio case study demonstrates an end-to-end transportation network strategy workflow. It combines shipment and carrier-rate analysis, service-level constraints, negotiated-rate scenarios, break-even analysis, executive reporting, client requirements, data architecture, validation controls, operational feasibility checks, and an implementation handoff plan. All data is simulated and intended to demonstrate analytical and solution-design capability.
A12: HOW THIS PROJECT MAPS TO A SOLUTIONS ARCHITECT ROLE
A13: Capability | B13: Portfolio Evidence | C13: Workbook Location
A14: Transportation Network Analysis | B14: Lane-level current versus modeled cost comparison | C14: Analysis / Dashboard
A15: Carrier Strategy & Procurement | B15: Service eligibility, negotiated-rate scenarios and break-even thresholds | C15: Analysis / Dashboard
A16: Cost Modeling | B16: Current cost, modeled cost, variance and sensitivity analysis | C16: Analysis
A17: Client Discovery | B17: Business objectives, priorities and success metrics | C17: Requirements & Solution Design
A18: Operational Feasibility | B18: Capacity, service, accessorial, systems and commercial gates | C18: Requirements & Solution Design
A19: SQL / Data Architecture | B19: Defined source-to-model flow and SQL transformation layer | C19: Requirements & Solution Design
A20: Power BI / Tableau | B20: Defined reporting layer and executive KPI outputs | C20: Requirements & Solution Design
A21: TMS / WMS | B21: Source-system responsibilities and implementation dependencies | C21: Requirements & Solution Design
A22: Data Validation | B22: Data quality rules and exception handling | C22: Requirements & Solution Design / Data Dictionary
A23: Implementation | B23: Phased workplan, decision gates and handoff artifacts | C23: Implementation & Handoff
